Workbook

Sheet Budget
A1: items | B1: jan | C1: Feb | D1: Mar | E1: apr | F1: may | G1: jun | H1: July | I1: Aug | J1: Sept | K1: Oct | L1: Nov | M1: Dec | N1: Total
A2: Income | B2: =Items!D2 -> 7543.02 | N2: =sum(B2:M2) -> 7543.02
N3: =sum(B3:M3) -> 0
A4: Life Insurance | B4: =Items!D86 -> 912.59 | N4: =sum(B4:M4) -> 912.59
A5: Cash App | B5: =Items!D14 -> 341 | H5: =SUM(D5+E5+F5+G5) -> 0 | N5: =sum(B5:M5) -> 341
A6: Car payment | B6: =Items!D25 -> 510 | H6: =SUM(D6+E6+F6+G6) -> 0 | N6: =sum(B6:M6) -> 510
A7: Car Insurance | B7: =Items!D79 -> 325.25 | H7: =SUM(D7+E7+F7+G7) -> 0 | N7: =sum(B7:M7) -> 325.25
A8: Child support | B8: =Items!D27 -> 600 | H8: =SUM(D8+E8+F8+G8) -> 0 | N8: =sum(B8:M8) -> 600
A9: Fitness | B9: =Items!D37 -> 23.06 | H9: =SUM(D9+E9+F9+G9) -> 0 | N9: =sum(B9:M9) -> 23.06
A10: Food | B10: =Items!D39 -> 208.04 | H10: =SUM(D10+E10+F10+G10) -> 0 | N10: =sum(B10:M10) -> 208.04
A11: Gas | B11: =Items!D67 -> 207.68 | H11: =SUM(D11+E11+F11+G11) -> 0 | N11: =sum(B11:M11) -> 207.68
A12: Haircut | B12: =Items!D83 -> 82.5 | H12: =SUM(D12+E12+F12+G12) -> 0 | N12: =Items!D83 -> 82.5
A13: Bank fee | B13: =Items!D10 -> 4.95 | H13: =SUM(D13+E13+F13+G13) -> 0 | N13: =sum(B13:M13) -> 4.95
A14: Internet & mobile | B14: =Items!D75 -> 63.35 | H14: =SUM(D14+E14+F14+G14) -> 0 | N14: =sum(B14:M14) -> 63.35
A15: Legal | B15: =Items!D77 -> 49 | H15: =SUM(D15+E15+F15+G15) -> 0 | N15: =sum(B15:M15) -> 49
A16: Membership | B16: =Items!D89 -> 149.97 | H16: =SUM(D16+E16+F16+G16) -> 0 | N16: =sum(B16:M16) -> 149.97
A17: Mortagage | B17: =Items!D91 -> 2600 | H17: =SUM(D17+E17+F17+G17) -> 0 | N17: =sum(B17:M17) -> 2600
A18: Mobile | B18: =Items!D94 -> 92.16 | N18: =Items!D94 -> 92.16
A19: Other | B19: =Items!D97 -> 511.76 | N19: =sum(B19:M19) -> 511.76
A20: Phone | B20: =Items!D102 -> 180 | H20: =SUM(D20+E20+F20+G20) -> 0 | N20: =sum(B20:M20) -> 180
A21: Saving fee | B21: =Items!D33 -> 2.97 | N21: =sum(B21:M21) -> 2.97
A22: Subscription | B22: =Items!D120 -> 324.21 | N22: =sum(B22:M22) -> 324.21
A23: Union dues | B23: =Items!D137 -> 201 | H23: =SUM(D23+E23+F23+G23) -> 0 | N23: =Items!D138 -> 201
A24: Cash App | B24: =Items!D14 -> 341 | N24: =sum(B24:M24) -> 341
A25: Saving | B25: =Items!D107 -> 166.73 | N25: =sum(B25:M25) -> 166.73
A26: Retail | B26: =Items!D104 -> 43 | N26: =sum(B26:M26) -> 43
A27: Tolls | B27: =Items!D130 -> 120 | N27: =sum(B27:M27) -> 120
A28: Monthly debt | B28: =sum(B4:B27) -> 8060.22 | N28: =sum(B28:M28) -> 8060.22
M31: Income | N31: =N2 -> 7543.02
M32: Debt | N32: =sum(N3:N27) -> 8060.22
N33: =sum(N31-N32) -> -517.2

Sheet Items
A1: Date | B1: Description | C1: Item | D1: Cost
A2: Income | D2: =sum(D3:D9) -> 7543.02 | E2: =sum(E3:E9) -> 0
A3: 46022 | B3: Income | C3: Direct Deposit | D3: 1100.22
A4: 45665 | B4: Income | C4: Direct Deposit | D4: 733.47
A5: 46037 | B5: Income | C5: Direct Deposit | D5: 1466.95
A6: 46044 | B6: Income | C6: Direct Deposit | D6: 1833.69
A7: 46050 | B7: Income | C7: Direct Deposit | D7: 1833.69
B8: Income | C8: Firestyle llc | D8: 575
A10: Bank Fee | D10: =D11 -> 4.95 | E10: =E11
A11: 46038 | B11: Banking Fee | C11: Maintenance Fee | D11: 4.95
A12: 46038 | B12: Bank fee | C12: Atm fee | D12: 2.5
A13: 46049 | B13: Bank fee | C13: Atm fee | D13: 2.5
A14: Cash App | D14: =SUM(D15:D24) -> 341 | E14: =SUM(E15:E24) -> 0
A15: 46027 | B15: Cash App | C15: Derrell Black Jr | D15: 10
A16: 46027 | B16: Cash App | C16: Derrell Black Jr | D16: 6
A17: 46027 | B17: Cash App | C17: Syron Smith | D17: 1
A18: 46027 | B18: Cash App | C18: James Moore | D18: 20
A19: 46028 | B19: Cash App | C19: Destiny | D19: 20
A20: 46034 | B20: Cash App | C20: Derrell Black jr | D20: 30
A21: 46037 | B21: Cash App | C21: Derrell Black jr | D21: 6
A22: 46041 | B22: Cash App | C22: Destiny | D22: 43
A23: 46045 | B23: Cash App | C23: James Moore | D23: 180
A24: 46046 | B24: cash app | C24: Derrell Black jr | D24: 25
A25: Car payment | D25: 510 | E25: 510
A26: 46037 | B26: Car payment | C26: Ally Finanacial | D26: =D25 -> 510
A27: Child support | D27: =sum(D28:D31) -> 600 | E27: =sum(E28:E31) -> 0
A28: 46028 | B28: Child support | C28: Expert pay | D28: 150
A29: 46042 | B29: Child support | C29: Expert Pay | D29: 150
A30: 46035 | B30: Child support | C30: Expert pay | D30: 150
A31: 46051 | B31: Child support | C31: Expert pay | D31: 150
A33: Fee | D33: =sum(D34:D36) -> 2.97
A34: 46027 | B34: Fee | C34: Opportun | D34: 0.99
A35: 46027 | B35: Fee | C35: Opportun | D35: 0.99
A36: 46044 | B36: Fee | C36: Opportun | D36: 0.99
A37: Fitness | D37: =D38 -> 23.06
A38: 46042 | B38: Fitness | C38: Plant Fitness | D38: 23.06
A39: Food | D39: =sum(D40:D60) -> 208.04
A40: 46024 | B40: Food | C40: Food truck | D40: 3.42
A41: 46024 | B41: Food | C41: Fox one | D41: 22.05
A42: 46027 | B42: Food | C42: Town & Country | D42: 11.25
...

Sheet March
A1: Date | B1: Description | C1: Item | E1: Cost
A2: Bank Fee | E2: =E3 -> 4.95
A3: 46038 | B3: Banking Fee | C3: Maintenance Fee | E3: 4.95
A4: Cash App | E4: =SUM(E5:E10) -> 87
A5: 46027 | B5: Cash App | C5: Derrell Black Jr | E5: 10
A6: 46027 | B6: Cash App | C6: Derrell Black Jr | E6: 6
A7: 46027 | B7: Cash App | C7: Syron Smith | E7: 1
A8: 46027 | B8: Cash App | C8: James Moore | E8: 20
A9: 46028 | B9: Cash App | C9: Destiny | E9: 20
A10: 46034 | B10: Cash App | C10: Derrell Black jr | E10: 30
A11: Child support | E11: =sum(E12:E14) -> 450
A12: 46028 | B12: Child support | C12: Expert pay | E12: 150
A13: 46042 | B13: Child support | C13: Expert Pay | E13: 150
A14: 46035 | B14: Child support | C14: Expert pay | E14: 150
A15: Fee | E15: =sum(E16:E17) -> 1.98
A16: 46027 | B16: Fee | C16: Opportun | E16: 0.99
A17: 46027 | B17: Fee | C17: Opportun | E17: 0.99
A18: Food | E18: =sum(E19:E34) -> 174.1
A19: 46024 | B19: Food | C19: Food truck | E19: 3.42
A20: 46024 | B20: Food | C20: Fox one | E20: 22.05
A21: 46027 | B21: Food | C21: Town & Country | E21: 11.25
A22: 46028 | B22: Food | C22: Food truck | E22: 5.69
A23: 46028 | B23: Food | C23: Town & Country | E23: 7.71
A24: 46030 | B24: Food | C24: Food truck | E24: 9.11
A25: 46030 | B25: food | C25: Dunkin' Donuts | E25: 4.79
A26: 46030 | B26: Food | C26: Town & Country | E26: 8.73
A27: 46034 | B27: Food | C27: Rosatis pizza | E27: 8.25
A28: 46034 | B28: Food | C28: Old fashion donuts | E28: 3.32
A29: 46034 | B29: food | C29: Sharks, fish, and chicken | E29: 24.06
A30: 46034 | B30: Food | C30: Town & Country | E30: 11.25
... A34: 46036 | B34: Food | C34: Ricky Rocket | E34: 13.92
A35: Gas | E35: =sum(E36:E37) -> 98.37
A36: 46027 | B36: Gas | C36: BP | E36: 53.48
A37: 46030 | B37: Gas | C37: BP | E37: 44.89
A38: Internet | E38: =E39 -> 63.35
A39: 46034 | B39: Internet | C39: Comcast internet | E39: 63.35
A40: Legal | E40: =E41 -> 49
A41: 46029 | B41: Legal | C41: Law depot | E41: 49
A42: Car insurance | E42: =sum(E43:E44) -> 290
A43: 46045 | B43: Car insurance | C43: Artisan and trucks | E43: 290
...

Sheet  Feb
A1: Date | B1: Description | C1: Item | D1: Cost
A2: Income | D2: =SUM(D3:D6) -> 7333.28
B3: Direct deposit | C3: Livewire | D3: 1833.32
B4: Direct deposit | C4: Livewire | D4: 1833.32
B5: Direct deposit | C5: Livewire | D5: 1833.32
B6: Direct deposit | C6: Livewire | D6: 1833.32
A7: Bank Fee | D7: =D9
B9: Banking Fee | C9: Maintenance Fee
A10: Cash App | D10: =SUM(D11:D16) -> 0
B11: Cash App | C11: Derrell Black Jr
B12: Cash App | C12: Derrell Black Jr
B13: Cash App | C13: Syron Smith
B14: Cash App | C14: James Moore
B15: Cash App | C15: Destiny
B16: Cash App | C16: Derrell Black jr
A17: Child support | D17: =sum(D18:D20) -> 0
B18: Child support | C18: Expert pay
B19: Child support | C19: Expert Pay
B20: Child support | C20: Expert pay
A21: Fee | D21: =sum(D22:D23) -> 0
B22: Fee | C22: Opportun
B23: Fee | C23: Opportun
A24: Food | D24: =sum(D25:D39) -> 0
B25: Food | C25: Food truck
B26: Food | C26: Town & Country
B27: Food | C27: Food truck
B28: Food | C28: Town & Country
B29: Food | C29: Food truck
B30: food | C30: Dunkin' Donuts
B31: Food | C31: Town & Country
B32: Food | C32: Rosatis pizza
B33: Food | C33: Old fashion donuts
B34: food | C34: Sharks, fish, and chicken
B35: Food | C35: Town & Country
B36: Food | C36: Ricky Rocket
... B39: Food | C39: Ricky Rocket
A40: Gas | D40: =sum(D41:D42) -> 0
B41: Gas | C41: BP
B42: Gas | C42: BP
A43: Internet | D43: =D44
...
